[2024-06-26T18:43:48.959+0000] {local_task_job_runner.py:120} INFO - ::group::Pre task execution logs
[2024-06-26T18:43:49.013+0000] {taskinstance.py:2076} INFO - Dependencies all met for dep_context=non-requeueable deps ti=<TaskInstance: Stage_1.run_bronze_job manual__2024-06-26T18:43:42.675852+00:00 [queued]>
[2024-06-26T18:43:49.027+0000] {taskinstance.py:2076} INFO - Dependencies all met for dep_context=requeueable deps ti=<TaskInstance: Stage_1.run_bronze_job manual__2024-06-26T18:43:42.675852+00:00 [queued]>
[2024-06-26T18:43:49.028+0000] {taskinstance.py:2306} INFO - Starting attempt 1 of 1
[2024-06-26T18:43:49.045+0000] {taskinstance.py:2330} INFO - Executing <Task(DockerOperator): run_bronze_job> on 2024-06-26 18:43:42.675852+00:00
[2024-06-26T18:43:49.056+0000] {logging_mixin.py:188} WARNING - /home/***/.local/lib/python3.12/site-packages/***/task/task_runner/standard_task_runner.py:61 DeprecationWarning: This process (pid=240) is multi-threaded, use of fork() may lead to deadlocks in the child.
[2024-06-26T18:43:49.057+0000] {standard_task_runner.py:63} INFO - Started process 241 to run task
[2024-06-26T18:43:49.055+0000] {standard_task_runner.py:90} INFO - Running: ['***', 'tasks', 'run', 'Stage_1', 'run_bronze_job', 'manual__2024-06-26T18:43:42.675852+00:00', '--job-id', '12', '--raw', '--subdir', 'DAGS_FOLDER/kafka_dag.py', '--cfg-path', '/tmp/tmplevxsibk']
[2024-06-26T18:43:49.058+0000] {standard_task_runner.py:91} INFO - Job 12: Subtask run_bronze_job
[2024-06-26T18:43:49.073+0000] {logging_mixin.py:188} WARNING - /home/***/.local/lib/python3.12/site-packages/***/settings.py:195 DeprecationWarning: The sql_alchemy_conn option in [core] has been moved to the sql_alchemy_conn option in [database] - the old setting has been used, but please update your config.
[2024-06-26T18:43:49.107+0000] {task_command.py:426} INFO - Running <TaskInstance: Stage_1.run_bronze_job manual__2024-06-26T18:43:42.675852+00:00 [running]> on host e1f7d869ee61
[2024-06-26T18:43:49.204+0000] {taskinstance.py:2648} INFO - Exporting env vars: AIRFLOW_CTX_DAG_OWNER='***' AIRFLOW_CTX_DAG_ID='Stage_1' AIRFLOW_CTX_TASK_ID='run_bronze_job' AIRFLOW_CTX_EXECUTION_DATE='2024-06-26T18:43:42.675852+00:00' AIRFLOW_CTX_TRY_NUMBER='1' AIRFLOW_CTX_DAG_RUN_ID='manual__2024-06-26T18:43:42.675852+00:00'
[2024-06-26T18:43:49.205+0000] {taskinstance.py:430} INFO - ::endgroup::
[2024-06-26T18:43:49.240+0000] {docker.py:493} INFO - Pulling docker image bitnami/spark:latest
[2024-06-26T18:43:50.570+0000] {docker.py:507} INFO - latest: Pulling from bitnami/spark
[2024-06-26T18:43:50.610+0000] {docker.py:507} INFO - 6d10d4f6c38d: Pulling fs layer
[2024-06-26T18:43:51.127+0000] {docker.py:507} INFO - 6d10d4f6c38d: Downloading
[2024-06-26T18:49:39.454+0000] {taskinstance.py:441} INFO - ::group::Post task execution logs
[2024-06-26T18:49:39.455+0000] {taskinstance.py:2905} ERROR - Task failed with exception
Traceback (most recent call last):
  File "/usr/local/lib/python3.12/http/client.py", line 579, in _get_chunk_left
    chunk_left = self._read_next_chunk_size()
                 ^^^^^^^^^^^^^^^^^^^^^^^^^^^^
  File "/usr/local/lib/python3.12/http/client.py", line 546, in _read_next_chunk_size
    return int(line, 16)
           ^^^^^^^^^^^^^
ValueError: invalid literal for int() with base 16: b''

During handling of the above exception, another exception occurred:

Traceback (most recent call last):
  File "/usr/local/lib/python3.12/http/client.py", line 595, in _read_chunked
    while (chunk_left := self._get_chunk_left()) is not None:
                         ^^^^^^^^^^^^^^^^^^^^^^
  File "/usr/local/lib/python3.12/http/client.py", line 581, in _get_chunk_left
    raise IncompleteRead(b'')
http.client.IncompleteRead: IncompleteRead(0 bytes read)

The above exception was the direct cause of the following exception:

Traceback (most recent call last):
  File "/home/airflow/.local/lib/python3.12/site-packages/urllib3/response.py", line 737, in _error_catcher
    yield
  File "/home/airflow/.local/lib/python3.12/site-packages/urllib3/response.py", line 862, in _raw_read
    data = self._fp_read(amt, read1=read1) if not fp_closed else b""
           ^^^^^^^^^^^^^^^^^^^^^^^^^^^^^^^
  File "/home/airflow/.local/lib/python3.12/site-packages/urllib3/response.py", line 845, in _fp_read
    return self._fp.read(amt) if amt is not None else self._fp.read()
           ^^^^^^^^^^^^^^^^^^
  File "/usr/local/lib/python3.12/http/client.py", line 473, in read
    return self._read_chunked(amt)
           ^^^^^^^^^^^^^^^^^^^^^^^
  File "/usr/local/lib/python3.12/http/client.py", line 607, in _read_chunked
    raise IncompleteRead(b''.join(value)) from exc
http.client.IncompleteRead: IncompleteRead(0 bytes read)

The above exception was the direct cause of the following exception:

Traceback (most recent call last):
  File "/home/airflow/.local/lib/python3.12/site-packages/airflow/models/taskinstance.py", line 465, in _execute_task
    result = _execute_callable(context=context, **execute_callable_kwargs)
             ^^^^^^^^^^^^^^^^^^^^^^^^^^^^^^^^^^^^^^^^^^^^^^^^^^^^^^^^^^^^^
  File "/home/airflow/.local/lib/python3.12/site-packages/airflow/models/taskinstance.py", line 432, in _execute_callable
    return execute_callable(context=context, **execute_callable_kwargs)
           ^^^^^^^^^^^^^^^^^^^^^^^^^^^^^^^^^^^^^^^^^^^^^^^^^^^^^^^^^^^^
  File "/home/airflow/.local/lib/python3.12/site-packages/airflow/models/baseoperator.py", line 400, in wrapper
    return func(self, *args, **kwargs)
           ^^^^^^^^^^^^^^^^^^^^^^^^^^^
  File "/home/airflow/.local/lib/python3.12/site-packages/airflow/providers/docker/operators/docker.py", line 495, in execute
    for output in self.cli.pull(self.image, stream=True, decode=True):
  File "/home/airflow/.local/lib/python3.12/site-packages/docker/api/client.py", line 350, in _stream_helper
    yield from json_stream(self._stream_helper(response, False))
  File "/home/airflow/.local/lib/python3.12/site-packages/docker/utils/json_stream.py", line 61, in split_buffer
    for data in stream_as_text(stream):
  File "/home/airflow/.local/lib/python3.12/site-packages/docker/utils/json_stream.py", line 17, in stream_as_text
    for data in stream:
  File "/home/airflow/.local/lib/python3.12/site-packages/docker/api/client.py", line 355, in _stream_helper
    data = reader.read(1)
           ^^^^^^^^^^^^^^
  File "/home/airflow/.local/lib/python3.12/site-packages/urllib3/response.py", line 935, in read
    data = self._raw_read(amt)
           ^^^^^^^^^^^^^^^^^^^
  File "/home/airflow/.local/lib/python3.12/site-packages/urllib3/response.py", line 861, in _raw_read
    with self._error_catcher():
  File "/usr/local/lib/python3.12/contextlib.py", line 158, in __exit__
    self.gen.throw(value)
  File "/home/airflow/.local/lib/python3.12/site-packages/urllib3/response.py", line 764, in _error_catcher
    raise ProtocolError(f"Connection broken: {e!r}", e) from e
urllib3.exceptions.ProtocolError: ('Connection broken: IncompleteRead(0 bytes read)', IncompleteRead(0 bytes read))
[2024-06-26T18:49:39.486+0000] {local_task_job_runner.py:124} ERROR - Received SIGTERM. Terminating subprocesses
[2024-06-26T18:49:39.489+0000] {process_utils.py:132} INFO - Sending 15 to group 241. PIDs of all processes in the group: [241]
[2024-06-26T18:49:39.650+0000] {process_utils.py:87} INFO - Sending the signal 15 to group 241
[2024-06-26T18:49:39.669+0000] {taskinstance.py:2611} ERROR - Received SIGTERM. Terminating subprocesses.
[2024-06-26T18:49:39.670+0000] {docker.py:528} INFO - Stopping docker container
[2024-06-26T18:49:39.670+0000] {docker.py:530} INFO - Not attempting to kill container as it was not created
[2024-06-26T18:49:39.761+0000] {process_utils.py:80} INFO - Process psutil.Process(pid=241, status='terminated', exitcode=2, started='18:43:48') (241) terminated with exit code 2
[2024-06-26T18:49:39.762+0000] {local_task_job_runner.py:240} INFO - Task exited with return code 143
[2024-06-26T18:49:39.833+0000] {taskinstance.py:3498} INFO - 0 downstream tasks scheduled from follow-on schedule check
