[2024-07-01T19:20:01.316+0000] {local_task_job_runner.py:120} INFO - ::group::Pre task execution logs
[2024-07-01T19:20:01.369+0000] {taskinstance.py:2076} INFO - Dependencies all met for dep_context=non-requeueable deps ti=<TaskInstance: purchase_dag.create_lookup_table_script manual__2024-07-01T19:19:56.354665+00:00 [queued]>
[2024-07-01T19:20:01.384+0000] {taskinstance.py:2076} INFO - Dependencies all met for dep_context=requeueable deps ti=<TaskInstance: purchase_dag.create_lookup_table_script manual__2024-07-01T19:19:56.354665+00:00 [queued]>
[2024-07-01T19:20:01.384+0000] {taskinstance.py:2306} INFO - Starting attempt 1 of 1
[2024-07-01T19:20:01.406+0000] {taskinstance.py:2330} INFO - Executing <Task(PythonOperator): create_lookup_table_script> on 2024-07-01 19:19:56.354665+00:00
[2024-07-01T19:20:01.417+0000] {logging_mixin.py:188} WARNING - /home/***/.local/lib/python3.12/site-packages/***/task/task_runner/standard_task_runner.py:61 DeprecationWarning: This process (pid=189) is multi-threaded, use of fork() may lead to deadlocks in the child.
[2024-07-01T19:20:01.416+0000] {standard_task_runner.py:90} INFO - Running: ['***', 'tasks', 'run', 'purchase_dag', 'create_lookup_table_script', 'manual__2024-07-01T19:19:56.354665+00:00', '--job-id', '525', '--raw', '--subdir', 'DAGS_FOLDER/purchase_dag.py', '--cfg-path', '/tmp/tmpt8o5b3qj']
[2024-07-01T19:20:01.418+0000] {standard_task_runner.py:63} INFO - Started process 190 to run task
[2024-07-01T19:20:01.418+0000] {standard_task_runner.py:91} INFO - Job 525: Subtask create_lookup_table_script
[2024-07-01T19:20:01.438+0000] {logging_mixin.py:188} WARNING - /home/***/.local/lib/python3.12/site-packages/***/settings.py:195 DeprecationWarning: The sql_alchemy_conn option in [core] has been moved to the sql_alchemy_conn option in [database] - the old setting has been used, but please update your config.
[2024-07-01T19:20:01.487+0000] {task_command.py:426} INFO - Running <TaskInstance: purchase_dag.create_lookup_table_script manual__2024-07-01T19:19:56.354665+00:00 [running]> on host 0a37133e4d82
[2024-07-01T19:20:01.608+0000] {taskinstance.py:2648} INFO - Exporting env vars: AIRFLOW_CTX_DAG_OWNER='***' AIRFLOW_CTX_DAG_ID='purchase_dag' AIRFLOW_CTX_TASK_ID='create_lookup_table_script' AIRFLOW_CTX_EXECUTION_DATE='2024-07-01T19:19:56.354665+00:00' AIRFLOW_CTX_TRY_NUMBER='1' AIRFLOW_CTX_DAG_RUN_ID='manual__2024-07-01T19:19:56.354665+00:00'
[2024-07-01T19:20:01.609+0000] {taskinstance.py:430} INFO - ::endgroup::
[2024-07-01T19:20:01.649+0000] {taskinstance.py:441} INFO - ::group::Post task execution logs
[2024-07-01T19:20:01.650+0000] {taskinstance.py:2905} ERROR - Task failed with exception
Traceback (most recent call last):
  File "/home/airflow/.local/lib/python3.12/site-packages/airflow/models/taskinstance.py", line 465, in _execute_task
    result = _execute_callable(context=context, **execute_callable_kwargs)
             ^^^^^^^^^^^^^^^^^^^^^^^^^^^^^^^^^^^^^^^^^^^^^^^^^^^^^^^^^^^^^
  File "/home/airflow/.local/lib/python3.12/site-packages/airflow/models/taskinstance.py", line 432, in _execute_callable
    return execute_callable(context=context, **execute_callable_kwargs)
           ^^^^^^^^^^^^^^^^^^^^^^^^^^^^^^^^^^^^^^^^^^^^^^^^^^^^^^^^^^^^
  File "/home/airflow/.local/lib/python3.12/site-packages/airflow/models/baseoperator.py", line 400, in wrapper
    return func(self, *args, **kwargs)
           ^^^^^^^^^^^^^^^^^^^^^^^^^^^
  File "/home/airflow/.local/lib/python3.12/site-packages/airflow/operators/python.py", line 235, in execute
    return_value = self.execute_callable()
                   ^^^^^^^^^^^^^^^^^^^^^^^
  File "/home/airflow/.local/lib/python3.12/site-packages/airflow/operators/python.py", line 252, in execute_callable
    return self.python_callable(*self.op_args, **self.op_kwargs)
           ^^^^^^^^^^^^^^^^^^^^^^^^^^^^^^^^^^^^^^^^^^^^^^^^^^^^^
  File "/opt/airflow/dags/create_lookup_table_script.py", line 72, in create_lookup_table
    cur.execute(insert_script)
psycopg2.errors.UndefinedColumn: column "item_category" of relation "lookup_category" does not exist
LINE 1: INSERT INTO lookup_category (item_name, item_category) VALUE...
                                                ^

[2024-07-01T19:20:01.661+0000] {taskinstance.py:1206} INFO - Marking task as FAILED. dag_id=purchase_dag, task_id=create_lookup_table_script, run_id=manual__2024-07-01T19:19:56.354665+00:00, execution_date=20240701T191956, start_date=20240701T192001, end_date=20240701T192001
[2024-07-01T19:20:01.676+0000] {standard_task_runner.py:110} ERROR - Failed to execute job 525 for task create_lookup_table_script (column "item_category" of relation "lookup_category" does not exist
LINE 1: INSERT INTO lookup_category (item_name, item_category) VALUE...
                                                ^
; 190)
[2024-07-01T19:20:01.713+0000] {local_task_job_runner.py:240} INFO - Task exited with return code 1
[2024-07-01T19:20:01.736+0000] {taskinstance.py:3498} INFO - 0 downstream tasks scheduled from follow-on schedule check
[2024-07-01T19:20:01.739+0000] {local_task_job_runner.py:222} INFO - ::endgroup::
