[2024-06-26T19:10:47.356+0000] {local_task_job_runner.py:120} INFO - ::group::Pre task execution logs
[2024-06-26T19:10:47.400+0000] {taskinstance.py:2076} INFO - Dependencies all met for dep_context=non-requeueable deps ti=<TaskInstance: Stage_1.run_bronze_job manual__2024-06-26T19:10:40.718745+00:00 [queued]>
[2024-06-26T19:10:47.413+0000] {taskinstance.py:2076} INFO - Dependencies all met for dep_context=requeueable deps ti=<TaskInstance: Stage_1.run_bronze_job manual__2024-06-26T19:10:40.718745+00:00 [queued]>
[2024-06-26T19:10:47.414+0000] {taskinstance.py:2306} INFO - Starting attempt 1 of 1
[2024-06-26T19:10:47.429+0000] {taskinstance.py:2330} INFO - Executing <Task(DockerOperator): run_bronze_job> on 2024-06-26 19:10:40.718745+00:00
[2024-06-26T19:10:47.437+0000] {logging_mixin.py:188} WARNING - /home/***/.local/lib/python3.12/site-packages/***/task/task_runner/standard_task_runner.py:61 DeprecationWarning: This process (pid=391) is multi-threaded, use of fork() may lead to deadlocks in the child.
[2024-06-26T19:10:47.438+0000] {standard_task_runner.py:63} INFO - Started process 392 to run task
[2024-06-26T19:10:47.437+0000] {standard_task_runner.py:90} INFO - Running: ['***', 'tasks', 'run', 'Stage_1', 'run_bronze_job', 'manual__2024-06-26T19:10:40.718745+00:00', '--job-id', '28', '--raw', '--subdir', 'DAGS_FOLDER/kafka_dag.py', '--cfg-path', '/tmp/tmpf_v2d5lf']
[2024-06-26T19:10:47.439+0000] {standard_task_runner.py:91} INFO - Job 28: Subtask run_bronze_job
[2024-06-26T19:10:47.454+0000] {logging_mixin.py:188} WARNING - /home/***/.local/lib/python3.12/site-packages/***/settings.py:195 DeprecationWarning: The sql_alchemy_conn option in [core] has been moved to the sql_alchemy_conn option in [database] - the old setting has been used, but please update your config.
[2024-06-26T19:10:47.490+0000] {task_command.py:426} INFO - Running <TaskInstance: Stage_1.run_bronze_job manual__2024-06-26T19:10:40.718745+00:00 [running]> on host 09fe08554062
[2024-06-26T19:10:47.594+0000] {taskinstance.py:2648} INFO - Exporting env vars: AIRFLOW_CTX_DAG_OWNER='***' AIRFLOW_CTX_DAG_ID='Stage_1' AIRFLOW_CTX_TASK_ID='run_bronze_job' AIRFLOW_CTX_EXECUTION_DATE='2024-06-26T19:10:40.718745+00:00' AIRFLOW_CTX_TRY_NUMBER='1' AIRFLOW_CTX_DAG_RUN_ID='manual__2024-06-26T19:10:40.718745+00:00'
[2024-06-26T19:10:47.595+0000] {taskinstance.py:430} INFO - ::endgroup::
[2024-06-26T19:10:47.631+0000] {docker.py:366} INFO - Starting docker container from image bitnami/spark:latest
[2024-06-26T19:10:47.634+0000] {docker.py:374} WARNING - Using remote engine or docker-in-docker and mounting temporary volume from host is not supported. Falling back to `mount_tmp_dir=False` mode. You can set `mount_tmp_dir` parameter to False to disable mounting and remove the warning
[2024-06-26T19:10:48.103+0000] {docker.py:436} INFO - [38;5;6mspark [38;5;5m19:10:48.10 [0m[38;5;2mINFO [0m ==>
[2024-06-26T19:10:48.105+0000] {docker.py:436} INFO - [38;5;6mspark [38;5;5m19:10:48.10 [0m[38;5;2mINFO [0m ==> [1mWelcome to the Bitnami spark container[0m
[2024-06-26T19:10:48.107+0000] {docker.py:436} INFO - [38;5;6mspark [38;5;5m19:10:48.10 [0m[38;5;2mINFO [0m ==> Subscribe to project updates by watching [1mhttps://github.com/bitnami/containers[0m
[2024-06-26T19:10:48.109+0000] {docker.py:436} INFO - [38;5;6mspark [38;5;5m19:10:48.10 [0m[38;5;2mINFO [0m ==> Submit issues and feature requests at [1mhttps://github.com/bitnami/containers/issues[0m
[2024-06-26T19:10:48.111+0000] {docker.py:436} INFO - [38;5;6mspark [38;5;5m19:10:48.11 [0m[38;5;2mINFO [0m ==> Upgrade to Tanzu Application Catalog for production environments to access custom-configured and pre-packaged software components. Gain enhanced features, including Software Bill of Materials (SBOM), CVE scan result reports, and VEX documents. To learn more, visit [1mhttps://bitnami.com/enterprise[0m
[2024-06-26T19:10:48.113+0000] {docker.py:436} INFO - [38;5;6mspark [38;5;5m19:10:48.11 [0m[38;5;2mINFO [0m ==>
[2024-06-26T19:10:48.125+0000] {docker.py:436} INFO - 
[2024-06-26T19:10:50.847+0000] {docker.py:436} INFO - :: loading settings :: url = jar:file:/opt/bitnami/spark/jars/ivy-2.5.1.jar!/org/apache/ivy/core/settings/ivysettings.xml
[2024-06-26T19:10:50.945+0000] {docker.py:436} INFO - Ivy Default Cache set to: /opt/bitnami/spark/.ivy2/cache
The jars for the packages stored in: /opt/bitnami/spark/.ivy2/jars
[2024-06-26T19:10:50.955+0000] {docker.py:436} INFO - org.apache.spark#spark-sql-kafka-0-10_2.12 added as a dependency
[2024-06-26T19:10:50.956+0000] {docker.py:436} INFO - org.postgresql#postgresql added as a dependency
[2024-06-26T19:10:50.957+0000] {docker.py:436} INFO - :: resolving dependencies :: org.apache.spark#spark-submit-parent-392db0eb-73b2-4662-9807-8c17c5fa0da3;1.0
[2024-06-26T19:10:50.958+0000] {docker.py:436} INFO - confs: [default]
[2024-06-26T19:10:51.214+0000] {docker.py:436} INFO - You probably access the destination server through a proxy server that is not well configured.
[2024-06-26T19:10:51.215+0000] {docker.py:436} INFO - You probably access the destination server through a proxy server that is not well configured.
[2024-06-26T19:10:51.219+0000] {docker.py:436} INFO - You probably access the destination server through a proxy server that is not well configured.
[2024-06-26T19:10:51.220+0000] {docker.py:436} INFO - You probably access the destination server through a proxy server that is not well configured.
[2024-06-26T19:10:51.229+0000] {docker.py:436} INFO - You probably access the destination server through a proxy server that is not well configured.
[2024-06-26T19:10:51.231+0000] {docker.py:436} INFO - You probably access the destination server through a proxy server that is not well configured.
[2024-06-26T19:10:51.233+0000] {docker.py:436} INFO - You probably access the destination server through a proxy server that is not well configured.
[2024-06-26T19:10:51.234+0000] {docker.py:436} INFO - You probably access the destination server through a proxy server that is not well configured.
[2024-06-26T19:10:51.261+0000] {docker.py:436} INFO - :: resolution report :: resolve 303ms :: artifacts dl 0ms
[2024-06-26T19:10:51.262+0000] {docker.py:436} INFO - :: modules in use:
[2024-06-26T19:10:51.262+0000] {docker.py:436} INFO - ---------------------------------------------------------------------
[2024-06-26T19:10:51.263+0000] {docker.py:436} INFO - |                  |            modules            ||   artifacts   |
[2024-06-26T19:10:51.263+0000] {docker.py:436} INFO - |       conf       | number| search|dwnlded|evicted|| number|dwnlded|
[2024-06-26T19:10:51.263+0000] {docker.py:436} INFO - ---------------------------------------------------------------------
[2024-06-26T19:10:51.264+0000] {docker.py:436} INFO - |      default     |   2   |   0   |   0   |   0   ||   0   |   0   |
	---------------------------------------------------------------------
[2024-06-26T19:10:51.267+0000] {docker.py:436} INFO - :: problems summary ::
:::: WARNINGS
[2024-06-26T19:10:51.268+0000] {docker.py:436} INFO - Host repo1.maven.org not found. url=https://repo1.maven.org/maven2/org/apache/spark/spark-sql-kafka-0-10_2.12/3.3.0/spark-sql-kafka-0-10_2.12-3.3.0.pom

	Host repo1.maven.org not found. url=https://repo1.maven.org/maven2/org/apache/spark/spark-sql-kafka-0-10_2.12/3.3.0/spark-sql-kafka-0-10_2.12-3.3.0.jar

	Host repos.spark-packages.org not found. url=https://repos.spark-packages.org/org/apache/spark/spark-sql-kafka-0-10_2.12/3.3.0/spark-sql-kafka-0-10_2.12-3.3.0.pom

	Host repos.spark-packages.org not found. url=https://repos.spark-packages.org/org/apache/spark/spark-sql-kafka-0-10_2.12/3.3.0/spark-sql-kafka-0-10_2.12-3.3.0.jar

		module not found: org.apache.spark#spark-sql-kafka-0-10_2.12;3.3.0

	==== local-m2-cache: tried

	  file:/opt/bitnami/spark/.m2/repository/org/apache/spark/spark-sql-kafka-0-10_2.12/3.3.0/spark-sql-kafka-0-10_2.12-3.3.0.pom

	  -- artifact org.apache.spark#spark-sql-kafka-0-10_2.12;3.3.0!spark-sql-kafka-0-10_2.12.jar:

	  file:/opt/bitnami/spark/.m2/repository/org/apache/spark/spark-sql-kafka-0-10_2.12/3.3.0/spark-sql-kafka-0-10_2.12-3.3.0.jar

	==== local-ivy-cache: tried

	  /opt/bitnami/spark/.ivy2/local/org.apache.spark/spark-sql-kafka-0-10_2.12/3.3.0/ivys/ivy.xml

	  -- artifact org.apache.spark#spark-sql-kafka-0-10_2.12;3.3.0!spark-sql-kafka-0-10_2.12.jar:

	  /opt/bitnami/spark/.ivy2/local/org.apache.spark/spark-sql-kafka-0-10_2.12/3.3.0/jars/spark-sql-kafka-0-10_2.12.jar

	==== central: tried

	  https://repo1.maven.org/maven2/org/apache/spark/spark-sql-kafka-0-10_2.12/3.3.0/spark-sql-kafka-0-10_2.12-3.3.0.pom

	  -- artifact org.apache.spark#spark-sql-kafka-0-10_2.12;3.3.0!spark-sql-kafka-0-10_2.12.jar:

	  https://repo1.maven.org/maven2/org/apache/spark/spark-sql-kafka-0-10_2.12/3.3.0/spark-sql-kafka-0-10_2.12-3.3.0.jar

	==== spark-packages: tried

	  https://repos.spark-packages.org/org/apache/spark/spark-sql-kafka-0-10_2.12/3.3.0/spark-sql-kafka-0-10_2.12-3.3.0.pom

	  -- artifact org.apache.spark#spark-sql-kafka-0-10_2.12;3.3.0!spark-sql-kafka-0-10_2.12.jar:

	  https://repos.spark-packages.org/org/apache/spark/spark-sql-kafka-0-10_2.12/3.3.0/spark-sql-kafka-0-10_2.12-3.3.0.jar

	Host repo1.maven.org not found. url=https://repo1.maven.org/maven2/org/postgresql/postgresql/42.2.2/postgresql-42.2.2.pom

	Host repo1.maven.org not found. url=https://repo1.maven.org/maven2/org/postgresql/postgresql/42.2.2/postgresql-42.2.2.jar

	Host repos.spark-packages.org not found. url=https://repos.spark-packages.org/org/postgresql/postgresql/42.2.2/postgresql-42.2.2.pom

	Host repos.spark-packages.org not found. url=https://repos.spark-packages.org/org/postgresql/postgresql/42.2.2/postgresql-42.2.2.jar

		module not found: org.postgresql#postgresql;42.2.2

	==== local-m2-cache: tried

	  file:/opt/bitnami/spark/.m2/repository/org/postgresql/postgresql/42.2.2/postgresql-42.2.2.pom

	  -- artifact org.postgresql#postgresql;42.2.2!postgresql.jar:

	  file:/opt/bitnami/spark/.m2/repository/org/postgresql/postgresql/42.2.2/postgresql-42.2.2.jar

	==== local-ivy-cache: tried

	  /opt/bitnami/spark/.ivy2/local/org.postgresql/postgresql/42.2.2/ivys/ivy.xml

	  -- artifact org.postgresql#postgresql;42.2.2!postgresql.jar:

	  /opt/bitnami/spark/.ivy2/local/org.postgresql/postgresql/42.2.2/jars/postgresql.jar

	==== central: tried

	  https://repo1.maven.org/maven2/org/postgresql/postgresql/42.2.2/postgresql-42.2.2.pom

	  -- artifact org.postgresql#postgresql;42.2.2!postgresql.jar:

	  https://repo1.maven.org/maven2/org/postgresql/postgresql/42.2.2/postgresql-42.2.2.jar

	==== spark-packages: tried

	  https://repos.spark-packages.org/org/postgresql/postgresql/42.2.2/postgresql-42.2.2.pom

	  -- artifact org.postgresql#postgresql;42.2.2!postgresql.jar:

	  https://repos.spark-packages.org/org/postgresql/postgresql/42.2.2/postgresql-42.2.2.jar

		::::::::::::::::::::::::::::::::::::::::::::::

		::          UNRESOLVED DEPENDENCIES         ::

		::::::::::::::::::::::::::::::::::::::::::::::

		:: org.apache.spark#spark-sql-kafka-0-10_2.12;3.3.0: not found

		:: org.postgresql#postgresql;42.2.2: not found

		::::::::::::::::::::::::::::::::::::::::::::::



:: USE VERBOSE OR DEBUG MESSAGE LEVEL FOR MORE DETAILS
[2024-06-26T19:10:51.269+0000] {docker.py:436} INFO - Exception in thread "main"
[2024-06-26T19:10:51.270+0000] {docker.py:436} INFO - java.lang.RuntimeException: [unresolved dependency: org.apache.spark#spark-sql-kafka-0-10_2.12;3.3.0: not found, unresolved dependency: org.postgresql#postgresql;42.2.2: not found]
[2024-06-26T19:10:51.271+0000] {docker.py:436} INFO - at org.apache.spark.deploy.SparkSubmitUtils$.resolveMavenCoordinates(SparkSubmit.scala:1608)
	at org.apache.spark.util.DependencyUtils$.resolveMavenDependencies(DependencyUtils.scala:185)
	at org.apache.spark.deploy.SparkSubmit.prepareSubmitEnvironment(SparkSubmit.scala:334)
	at org.apache.spark.deploy.SparkSubmit.org$apache$spark$deploy$SparkSubmit$$runMain(SparkSubmit.scala:964)
	at org.apache.spark.deploy.SparkSubmit.doRunMain$1(SparkSubmit.scala:194)
	at org.apache.spark.deploy.SparkSubmit.submit(SparkSubmit.scala:217)
	at org.apache.spark.deploy.SparkSubmit.doSubmit(SparkSubmit.scala:91)
	at org.apache.spark.deploy.SparkSubmit$$anon$2.doSubmit(SparkSubmit.scala:1120)
	at org.apache.spark.deploy.SparkSubmit$.main(SparkSubmit.scala:1129)
	at org.apache.spark.deploy.SparkSubmit.main(SparkSubmit.scala)
[2024-06-26T19:10:51.501+0000] {taskinstance.py:441} INFO - ::group::Post task execution logs
[2024-06-26T19:10:51.511+0000] {taskinstance.py:2905} ERROR - Task failed with exception
Traceback (most recent call last):
  File "/home/airflow/.local/lib/python3.12/site-packages/docker/api/client.py", line 265, in _raise_for_status
    response.raise_for_status()
  File "/home/airflow/.local/lib/python3.12/site-packages/requests/models.py", line 1021, in raise_for_status
    raise HTTPError(http_error_msg, response=self)
requests.exceptions.HTTPError: 400 Client Error: Bad Request for url: http://docker-proxy:2375/v1.45/containers/create

The above exception was the direct cause of the following exception:

Traceback (most recent call last):
  File "/home/airflow/.local/lib/python3.12/site-packages/airflow/providers/docker/operators/docker.py", line 371, in _run_image
    return self._run_image_with_mounts([*self.mounts, tmp_mount], add_tmp_variable=True)
           ^^^^^^^^^^^^^^^^^^^^^^^^^^^^^^^^^^^^^^^^^^^^^^^^^^^^^^^^^^^^^^^^^^^^^^^^^^^^^
  File "/home/airflow/.local/lib/python3.12/site-packages/airflow/providers/docker/operators/docker.py", line 398, in _run_image_with_mounts
    self.container = self.cli.create_container(
                     ^^^^^^^^^^^^^^^^^^^^^^^^^^
  File "/home/airflow/.local/lib/python3.12/site-packages/docker/api/container.py", line 439, in create_container
    return self.create_container_from_config(config, name, platform)
           ^^^^^^^^^^^^^^^^^^^^^^^^^^^^^^^^^^^^^^^^^^^^^^^^^^^^^^^^^
  File "/home/airflow/.local/lib/python3.12/site-packages/docker/api/container.py", line 456, in create_container_from_config
    return self._result(res, True)
           ^^^^^^^^^^^^^^^^^^^^^^^
  File "/home/airflow/.local/lib/python3.12/site-packages/docker/api/client.py", line 271, in _result
    self._raise_for_status(response)
  File "/home/airflow/.local/lib/python3.12/site-packages/docker/api/client.py", line 267, in _raise_for_status
    raise create_api_error_from_http_exception(e) from e
          ^^^^^^^^^^^^^^^^^^^^^^^^^^^^^^^^^^^^^^^
  File "/home/airflow/.local/lib/python3.12/site-packages/docker/errors.py", line 39, in create_api_error_from_http_exception
    raise cls(e, response=response, explanation=explanation) from e
docker.errors.APIError: 400 Client Error for http://docker-proxy:2375/v1.45/containers/create: Bad Request ("invalid mount config for type "bind": bind source path does not exist: /tmp/airflowtmp2ysw79n4")

During handling of the above exception, another exception occurred:

Traceback (most recent call last):
  File "/home/airflow/.local/lib/python3.12/site-packages/airflow/models/taskinstance.py", line 465, in _execute_task
    result = _execute_callable(context=context, **execute_callable_kwargs)
             ^^^^^^^^^^^^^^^^^^^^^^^^^^^^^^^^^^^^^^^^^^^^^^^^^^^^^^^^^^^^^
  File "/home/airflow/.local/lib/python3.12/site-packages/airflow/models/taskinstance.py", line 432, in _execute_callable
    return execute_callable(context=context, **execute_callable_kwargs)
           ^^^^^^^^^^^^^^^^^^^^^^^^^^^^^^^^^^^^^^^^^^^^^^^^^^^^^^^^^^^^
  File "/home/airflow/.local/lib/python3.12/site-packages/airflow/models/baseoperator.py", line 400, in wrapper
    return func(self, *args, **kwargs)
           ^^^^^^^^^^^^^^^^^^^^^^^^^^^
  File "/home/airflow/.local/lib/python3.12/site-packages/airflow/providers/docker/operators/docker.py", line 509, in execute
    return self._run_image()
           ^^^^^^^^^^^^^^^^^
  File "/home/airflow/.local/lib/python3.12/site-packages/airflow/providers/docker/operators/docker.py", line 380, in _run_image
    return self._run_image_with_mounts(self.mounts, add_tmp_variable=False)
           ^^^^^^^^^^^^^^^^^^^^^^^^^^^^^^^^^^^^^^^^^^^^^^^^^^^^^^^^^^^^^^^^
  File "/home/airflow/.local/lib/python3.12/site-packages/airflow/providers/docker/operators/docker.py", line 444, in _run_image_with_mounts
    raise DockerContainerFailedException(f"Docker container failed: {result!r}", logs=log_lines)
airflow.providers.docker.exceptions.DockerContainerFailedException: Docker container failed: {'StatusCode': 1}
[2024-06-26T19:10:51.519+0000] {taskinstance.py:1206} INFO - Marking task as FAILED. dag_id=Stage_1, task_id=run_bronze_job, run_id=manual__2024-06-26T19:10:40.718745+00:00, execution_date=20240626T191040, start_date=20240626T191047, end_date=20240626T191051
[2024-06-26T19:10:51.534+0000] {standard_task_runner.py:110} ERROR - Failed to execute job 28 for task run_bronze_job (Docker container failed: {'StatusCode': 1}; 392)
[2024-06-26T19:10:51.565+0000] {local_task_job_runner.py:240} INFO - Task exited with return code 1
[2024-06-26T19:10:51.584+0000] {taskinstance.py:3498} INFO - 0 downstream tasks scheduled from follow-on schedule check
[2024-06-26T19:10:51.587+0000] {local_task_job_runner.py:222} INFO - ::endgroup::
