[2024-06-28T15:36:05.510+0000] {local_task_job_runner.py:120} INFO - ::group::Pre task execution logs
[2024-06-28T15:36:05.592+0000] {taskinstance.py:2076} INFO - Dependencies all met for dep_context=non-requeueable deps ti=<TaskInstance: Stage_1.table_creations manual__2024-06-28T15:36:00.965628+00:00 [queued]>
[2024-06-28T15:36:05.616+0000] {taskinstance.py:2076} INFO - Dependencies all met for dep_context=requeueable deps ti=<TaskInstance: Stage_1.table_creations manual__2024-06-28T15:36:00.965628+00:00 [queued]>
[2024-06-28T15:36:05.617+0000] {taskinstance.py:2306} INFO - Starting attempt 1 of 1
[2024-06-28T15:36:05.656+0000] {taskinstance.py:2330} INFO - Executing <Task(PythonOperator): table_creations> on 2024-06-28 15:36:00.965628+00:00
[2024-06-28T15:36:05.670+0000] {logging_mixin.py:188} WARNING - /home/***/.local/lib/python3.12/site-packages/***/task/task_runner/standard_task_runner.py:61 DeprecationWarning: This process (pid=455) is multi-threaded, use of fork() may lead to deadlocks in the child.
[2024-06-28T15:36:05.673+0000] {standard_task_runner.py:63} INFO - Started process 457 to run task
[2024-06-28T15:36:05.671+0000] {standard_task_runner.py:90} INFO - Running: ['***', 'tasks', 'run', 'Stage_1', 'table_creations', 'manual__2024-06-28T15:36:00.965628+00:00', '--job-id', '454', '--raw', '--subdir', 'DAGS_FOLDER/kafka_dag.py', '--cfg-path', '/tmp/tmppgt223l2']
[2024-06-28T15:36:05.685+0000] {standard_task_runner.py:91} INFO - Job 454: Subtask table_creations
[2024-06-28T15:36:05.717+0000] {logging_mixin.py:188} WARNING - /home/***/.local/lib/python3.12/site-packages/***/settings.py:195 DeprecationWarning: The sql_alchemy_conn option in [core] has been moved to the sql_alchemy_conn option in [database] - the old setting has been used, but please update your config.
[2024-06-28T15:36:05.793+0000] {task_command.py:426} INFO - Running <TaskInstance: Stage_1.table_creations manual__2024-06-28T15:36:00.965628+00:00 [running]> on host 43cb83d08bb6
[2024-06-28T15:36:05.950+0000] {taskinstance.py:2648} INFO - Exporting env vars: AIRFLOW_CTX_DAG_OWNER='***' AIRFLOW_CTX_DAG_ID='Stage_1' AIRFLOW_CTX_TASK_ID='table_creations' AIRFLOW_CTX_EXECUTION_DATE='2024-06-28T15:36:00.965628+00:00' AIRFLOW_CTX_TRY_NUMBER='1' AIRFLOW_CTX_DAG_RUN_ID='manual__2024-06-28T15:36:00.965628+00:00'
[2024-06-28T15:36:05.951+0000] {taskinstance.py:430} INFO - ::endgroup::
[2024-06-28T15:36:05.978+0000] {logging_mixin.py:188} INFO - Table 'bronze_grocery_purchase' created successfully.
[2024-06-28T15:36:05.980+0000] {taskinstance.py:441} INFO - ::group::Post task execution logs
[2024-06-28T15:36:05.980+0000] {taskinstance.py:2905} ERROR - Task failed with exception
Traceback (most recent call last):
  File "/home/airflow/.local/lib/python3.12/site-packages/airflow/models/taskinstance.py", line 465, in _execute_task
    result = _execute_callable(context=context, **execute_callable_kwargs)
             ^^^^^^^^^^^^^^^^^^^^^^^^^^^^^^^^^^^^^^^^^^^^^^^^^^^^^^^^^^^^^
  File "/home/airflow/.local/lib/python3.12/site-packages/airflow/models/taskinstance.py", line 432, in _execute_callable
    return execute_callable(context=context, **execute_callable_kwargs)
           ^^^^^^^^^^^^^^^^^^^^^^^^^^^^^^^^^^^^^^^^^^^^^^^^^^^^^^^^^^^^
  File "/home/airflow/.local/lib/python3.12/site-packages/airflow/models/baseoperator.py", line 400, in wrapper
    return func(self, *args, **kwargs)
           ^^^^^^^^^^^^^^^^^^^^^^^^^^^
  File "/home/airflow/.local/lib/python3.12/site-packages/airflow/operators/python.py", line 235, in execute
    return_value = self.execute_callable()
                   ^^^^^^^^^^^^^^^^^^^^^^^
  File "/home/airflow/.local/lib/python3.12/site-packages/airflow/operators/python.py", line 252, in execute_callable
    return self.python_callable(*self.op_args, **self.op_kwargs)
           ^^^^^^^^^^^^^^^^^^^^^^^^^^^^^^^^^^^^^^^^^^^^^^^^^^^^^
  File "/opt/airflow/dags/table_creations.py", line 49, in create_tables
    cursor.execute(silver_sql)
psycopg2.errors.UniqueViolation: duplicate key value violates unique constraint "pg_type_typname_nsp_index"
DETAIL:  Key (typname, typnamespace)=(silver_grocery_purchase_id_seq, 2200) already exists.

[2024-06-28T15:36:05.994+0000] {taskinstance.py:1206} INFO - Marking task as FAILED. dag_id=Stage_1, task_id=table_creations, run_id=manual__2024-06-28T15:36:00.965628+00:00, execution_date=20240628T153600, start_date=20240628T153605, end_date=20240628T153605
[2024-06-28T15:36:06.008+0000] {standard_task_runner.py:110} ERROR - Failed to execute job 454 for task table_creations (duplicate key value violates unique constraint "pg_type_typname_nsp_index"
DETAIL:  Key (typname, typnamespace)=(silver_grocery_purchase_id_seq, 2200) already exists.
; 457)
[2024-06-28T15:36:06.024+0000] {local_task_job_runner.py:240} INFO - Task exited with return code 1
[2024-06-28T15:36:06.061+0000] {taskinstance.py:3498} INFO - 0 downstream tasks scheduled from follow-on schedule check
[2024-06-28T15:36:06.066+0000] {local_task_job_runner.py:222} INFO - ::endgroup::
