[2024-07-01T12:09:49.937+0000] {local_task_job_runner.py:120} INFO - ::group::Pre task execution logs
[2024-07-01T12:09:50.055+0000] {taskinstance.py:2076} INFO - Dependencies all met for dep_context=non-requeueable deps ti=<TaskInstance: purchase_dag.kafka_producer manual__2024-07-01T12:09:45.879437+00:00 [queued]>
[2024-07-01T12:09:50.077+0000] {taskinstance.py:2076} INFO - Dependencies all met for dep_context=requeueable deps ti=<TaskInstance: purchase_dag.kafka_producer manual__2024-07-01T12:09:45.879437+00:00 [queued]>
[2024-07-01T12:09:50.078+0000] {taskinstance.py:2306} INFO - Starting attempt 1 of 1
[2024-07-01T12:09:50.116+0000] {taskinstance.py:2330} INFO - Executing <Task(PythonOperator): kafka_producer> on 2024-07-01 12:09:45.879437+00:00
[2024-07-01T12:09:50.135+0000] {standard_task_runner.py:90} INFO - Running: ['***', 'tasks', 'run', 'purchase_dag', 'kafka_producer', 'manual__2024-07-01T12:09:45.879437+00:00', '--job-id', '468', '--raw', '--subdir', 'DAGS_FOLDER/purchase_dag.py', '--cfg-path', '/tmp/tmpqcf5_b6r']
[2024-07-01T12:09:50.141+0000] {standard_task_runner.py:91} INFO - Job 468: Subtask kafka_producer
[2024-07-01T12:09:50.150+0000] {logging_mixin.py:188} WARNING - /home/***/.local/lib/python3.12/site-packages/***/task/task_runner/standard_task_runner.py:61 DeprecationWarning: This process (pid=368) is multi-threaded, use of fork() may lead to deadlocks in the child.
[2024-07-01T12:09:50.151+0000] {standard_task_runner.py:63} INFO - Started process 369 to run task
[2024-07-01T12:09:50.181+0000] {logging_mixin.py:188} WARNING - /home/***/.local/lib/python3.12/site-packages/***/settings.py:195 DeprecationWarning: The sql_alchemy_conn option in [core] has been moved to the sql_alchemy_conn option in [database] - the old setting has been used, but please update your config.
[2024-07-01T12:09:50.282+0000] {task_command.py:426} INFO - Running <TaskInstance: purchase_dag.kafka_producer manual__2024-07-01T12:09:45.879437+00:00 [running]> on host 6d5f7889ee5a
[2024-07-01T12:09:50.465+0000] {taskinstance.py:2648} INFO - Exporting env vars: AIRFLOW_CTX_DAG_OWNER='***' AIRFLOW_CTX_DAG_ID='purchase_dag' AIRFLOW_CTX_TASK_ID='kafka_producer' AIRFLOW_CTX_EXECUTION_DATE='2024-07-01T12:09:45.879437+00:00' AIRFLOW_CTX_TRY_NUMBER='1' AIRFLOW_CTX_DAG_RUN_ID='manual__2024-07-01T12:09:45.879437+00:00'
[2024-07-01T12:09:50.466+0000] {taskinstance.py:430} INFO - ::endgroup::
[2024-07-01T12:09:50.491+0000] {taskinstance.py:441} INFO - ::group::Post task execution logs
[2024-07-01T12:09:50.492+0000] {taskinstance.py:2905} ERROR - Task failed with exception
Traceback (most recent call last):
  File "/home/airflow/.local/lib/python3.12/site-packages/airflow/models/taskinstance.py", line 465, in _execute_task
    result = _execute_callable(context=context, **execute_callable_kwargs)
             ^^^^^^^^^^^^^^^^^^^^^^^^^^^^^^^^^^^^^^^^^^^^^^^^^^^^^^^^^^^^^
  File "/home/airflow/.local/lib/python3.12/site-packages/airflow/models/taskinstance.py", line 432, in _execute_callable
    return execute_callable(context=context, **execute_callable_kwargs)
           ^^^^^^^^^^^^^^^^^^^^^^^^^^^^^^^^^^^^^^^^^^^^^^^^^^^^^^^^^^^^
  File "/home/airflow/.local/lib/python3.12/site-packages/airflow/models/baseoperator.py", line 400, in wrapper
    return func(self, *args, **kwargs)
           ^^^^^^^^^^^^^^^^^^^^^^^^^^^
  File "/home/airflow/.local/lib/python3.12/site-packages/airflow/operators/python.py", line 235, in execute
    return_value = self.execute_callable()
                   ^^^^^^^^^^^^^^^^^^^^^^^
  File "/home/airflow/.local/lib/python3.12/site-packages/airflow/operators/python.py", line 252, in execute_callable
    return self.python_callable(*self.op_args, **self.op_kwargs)
           ^^^^^^^^^^^^^^^^^^^^^^^^^^^^^^^^^^^^^^^^^^^^^^^^^^^^^
  File "/opt/airflow/dags/script_kafka.py", line 66, in kafka_producer_script
    dataresult=read_json_file(json_file_path)
               ^^^^^^^^^^^^^^^^^^^^^^^^^^^^^^
  File "/opt/airflow/dags/script_kafka.py", line 42, in read_json_file
    with open(file_path, 'r') as file:
         ^^^^^^^^^^^^^^^^^^^^
FileNotFoundError: [Errno 2] No such file or directory: '/home/arun/Desktop/dhaarini/DataEngineer/Projects/Project_1/src/purchases.json'
[2024-07-01T12:09:50.508+0000] {taskinstance.py:1206} INFO - Marking task as FAILED. dag_id=purchase_dag, task_id=kafka_producer, run_id=manual__2024-07-01T12:09:45.879437+00:00, execution_date=20240701T120945, start_date=20240701T120950, end_date=20240701T120950
[2024-07-01T12:09:50.528+0000] {standard_task_runner.py:110} ERROR - Failed to execute job 468 for task kafka_producer ([Errno 2] No such file or directory: '/home/arun/Desktop/dhaarini/DataEngineer/Projects/Project_1/src/purchases.json'; 369)
[2024-07-01T12:09:50.554+0000] {local_task_job_runner.py:240} INFO - Task exited with return code 1
[2024-07-01T12:09:50.587+0000] {taskinstance.py:3498} INFO - 0 downstream tasks scheduled from follow-on schedule check
[2024-07-01T12:09:50.593+0000] {local_task_job_runner.py:222} INFO - ::endgroup::
